<?xml version="1.0"?>

<sdf version="1.10">
    <model name="my_robot">

        <pose> 0 0 0 0 0 0 </pose>

        <link name="chassis">

            <pose> 0 0 0.2 0 0 0 </pose>

            <visual name="chassis_visual">
                <geometry>
                    <box>
                        <size> 0.3 1.0 0.1 </size>
                    </box>
                </geometry>
            </visual>

            <collision name="chassis_collision">
                <geometry>
                    <box>
                        <size> 0.3 1.0 0.1 </size>
                    </box>
                </geometry>
            </collision>

        </link>

        <link name="left_wheel">

            <pose> 0 0.55 0.2 1.5707 0 0 </pose>

            <visual name="visual">
                <geometry>
                    <cylinder>
                        <radius>0.2</radius>
                        <length>0.1</length>
                    </cylinder>
                </geometry>
            </visual>

            <collision name="collision">
                <geometry>
                    <cylinder>
                        <radius>0.2</radius>
                        <length>0.1</length>
                    </cylinder>
                </geometry>
            </collision>

        </link>

        <link name="right_wheel">

            <pose> 0 -0.55 0.2 1.5707 0 0 </pose>

            <visual name="visual">
                <geometry>
                    <cylinder>
                        <radius>0.2</radius>
                        <length>0.1</length>
                    </cylinder>
                </geometry>
            </visual>

            <collision name="collision">
                <geometry>
                    <cylinder>
                        <radius>0.2</radius>
                        <length>0.1</length>
                    </cylinder>
                </geometry>
            </collision>
            
        </link>

        <joint name="left_wheel_joint" type="revolute">

            <parent>chassis</parent>
            <child>left_wheel</child>

            <axis>
                <xyz> 1 0 0 </xyz>
            </axis>

        </joint>

        <joint name="right_wheel_joint" type="revolute">

            <parent>chassis</parent>
            <child>right_wheel</child>

            <axis>
                <xyz> 1 0 0 </xyz>
            </axis>

        </joint>

    </model>

</sdf>